Workbook

Sheet 說明
A1: Seal 評估記錄表
A2: 版本 v1.0｜2026-08-26｜配合《Seal 評估計畫書》與《Seal 易用性測試執行手冊》使用
A4: 怎麼用
A5: 黃底藍字 | B5: 要填的欄位。灰底的「範例」列示範格式，正式使用前請整列刪除（彙總會把範例算進去）。
A6: 黑字 | B6: 公式，不要覆蓋。彙總分頁的公式參考各分頁的整欄範圍，新增列不必改公式。
A7: 分頁
A8: A_受試者 | B8: Part A 受試者名單、分層、Part C 版面順序。
A9: A_任務記錄 | B9: 每位受試者 × 每個任務：時間、成功、錯誤、提示、任務後三題。
A10: A_觀察事件 | B10: 觀察員的事件流水帳，含嚴重度 0–4。
A11: A_SUS | B11: SUS 十題原始圈選值；分數自動計算；底部有平均與 95% CI。
A12: A_量表 | B12: 信任與驗證意願量表 V1–V6 與每工具三題。
A13: PartC_稽核 | B13: T6 稽核任務：每筆 code 的判定、信心、時間；自動算偵測與誤拒。
A14: B_執行記錄 | B14: Part B 每次執行的參數與系統自報計數（可由 seal_eval_collect.py 匯出後貼上）。
A15: B_埋點對照表 | B15: P01–P03 的埋點（已填）與新逐字稿的埋點；關鍵句必須逐字與逐字稿一致。
A16: B_埋點評分 | B16: 長格式：埋點ID × 條件 × run 的得分（1／0.5／0）。彙總用 AVERAGEIFS 算召回率。
A17: B_人工評分 | B17: 盲評：每筆 code 的參照對應、語證支持、過度推論、排除違反。條件欄請在盲評時隱藏。
A18: B_研究方向評分 | B18: 每個研究方向的有效性、可信度、語證扣合。
A19: B_盲評代碼 | B19: 條件代號 ↔ 盲評代碼對照；盲評期間請隱藏此分頁。
... A22: 彙總 | B22: 自動彙整 Part A／B／C 的主要指標。
A24: 代號
A25: 受試者 | B25: U01、U02…（與逐字稿的 P01–P03 區分）
A26: 模型條件 | B26: L1 = 4 GB 等級、L2 = qwen3:8b（預設）、L3 = 14b、L4 = 32b、C1／C2 = 雲端（經 seal_cloud_proxy）
A27: 埋點類型 | B27: E1 條件式選擇、E2 觸發→行動→結果、E3 界線／反覆做法、E4 轉變／矛盾、E5 第一人稱抱怨、E6 想做卻做不到、E7 訪員干擾句、E8 應排除、E9 跨受訪者對照點
A28: 成功 | B28: 1 = 獨立完成；0.5 = 需提示一次後完成；0 = 未完成或放棄
A29: 嚴重度 | B29: 0 非問題、1 表面、2 輕微、3 嚴重、4 災難（手冊附錄 A）

Sheet A_受試者
A1: A_受試者：名單與分層
A3: 受試者ID | B3: 日期 | C3: 分層（未曾／曾用 AI 輔助 coding） | D3: 身分／領域 | E3: 訪談場數 | F3: 電腦自評(1–7) | G3: 隱私顧慮 B7(1–7) | H3: Part C 版面順序 | I3: 主持人 | J3: 觀察員 | K3: 備註
A4: 範例 | B4: 2026-09-15 | C4: 未曾 | D4: 碩士生／教育 | E4: 5 | F4: 5 | G4: 6 | H4: AB | I4: CC | J4: PY | K4: 使用前刪除此列

Sheet A_任務記錄
A1: A_任務記錄：每位受試者 × 每個任務
A2: 主動時間 = 扣除模型運算等待；等待時間另填。任務後三題：難度、最卡、信任。
A3: 受試者ID | B3: 任務 | C3: 工具 | D3: 開始時間 | E3: 結束時間 | F3: 主動時間(分) | G3: 等待時間(分) | H3: 等待已跳過(Y/N) | I3: 成功(1/0.5/0) | J3: 錯誤數 | K3: 提示數 | L3: 難度(1–7) | M3: 信任(1–7) | N3: 最卡的地方 | O3: 備註
A4: 範例 | B4: T4 | C4: Seal Open Coding | D4: 10:42 | E4: 10:55 | F4: 9 | G4: 4 | H4: Y | I4: 0.5 | J4: 1 | K4: 1 | L4: 5 | M4: 4 | N4: 沒勾覆寫，以為跑完了 | O4: 使用前刪除此列

Sheet A_觀察事件
A1: A_觀察事件：事件流水帳
A3: 受試者ID | B3: 任務 | C3: 時間戳 | D3: 事件類型 | E3: 工具 | F3: 描述（做了／說了什麼） | G3: 嚴重度(0–4) | H3: 是否已在問題清單(編號)
A4: 範例 | B4: T1 | C4: 10:12 | D4: 困惑 | E4: Seal STT | F4: 在 %LOCALAPPDATA% 找不到輸出資料夾，回主畫面找了 1 分鐘 | G4: 2 | H4: I-03

Sheet A_SUS
A1: A_SUS：系統易用性量表
A2: 填原始圈選值 1–5；奇數題 (值−1)、偶數題 (5−值)，總和 ×2.5。
A3: 受試者ID | B3: Q1 | C3: Q2 | D3: Q3 | E3: Q4 | F3: Q5 | G3: Q6 | H3: Q7 | I3: Q8 | J3: Q9 | K3: Q10 | L3: 奇數題得分 | M3: 偶數題得分 | N3: SUS 分數
A4: 範例 | B4: 4 | C4: 2 | D4: 4 | E4: 2 | F4: 4 | G4: 2 | H4: 4 | I4: 2 | J4: 4 | K4: 3 | L4: =IF(COUNT(B4:K4)=10,(B4-1)+(D4-1)+(F4-1)+(H4-1)+(J4-1),"") -> 15 | M4: =IF(COUNT(B4:K4)=10,(5-C4)+(5-E4)+(5-G4)+(5-I4)+(5-K4),"") -> 14 | N4: =IF(COUNT(B4:K4)=10,(L4+M4)*2.5,"") -> 72.5
L5: =IF(COUNT(B5:K5)=10,(B5-1)+(D5-1)+(F5-1)+(H5-1)+(J5-1),"") | M5: =IF(COUNT(B5:K5)=10,(5-C5)+(5-E5)+(5-G5)+(5-I5)+(5-K5),"") | N5: =IF(COUNT(B5:K5)=10,(L5+M5)*2.5,"")
L6: =IF(COUNT(B6:K6)=10,(B6-1)+(D6-1)+(F6-1)+(H6-1)+(J6-1),"") | M6: =IF(COUNT(B6:K6)=10,(5-C6)+(5-E6)+(5-G6)+(5-I6)+(5-K6),"") | N6: =IF(COUNT(B6:K6)=10,(L6+M6)*2.5,"")
L7: =IF(COUNT(B7:K7)=10,(B7-1)+(D7-1)+(F7-1)+(H7-1)+(J7-1),"") | M7: =IF(COUNT(B7:K7)=10,(5-C7)+(5-E7)+(5-G7)+(5-I7)+(5-K7),"") | N7: =IF(COUNT(B7:K7)=10,(L7+M7)*2.5,"")
L8: =IF(COUNT(B8:K8)=10,(B8-1)+(D8-1)+(F8-1)+(H8-1)+(J8-1),"") | M8: =IF(COUNT(B8:K8)=10,(5-C8)+(5-E8)+(5-G8)+(5-I8)+(5-K8),"") | N8: =IF(COUNT(B8:K8)=10,(L8+M8)*2.5,"")
L9: =IF(COUNT(B9:K9)=10,(B9-1)+(D9-1)+(F9-1)+(H9-1)+(J9-1),"") | M9: =IF(COUNT(B9:K9)=10,(5-C9)+(5-E9)+(5-G9)+(5-I9)+(5-K9),"") | N9: =IF(COUNT(B9:K9)=10,(L9+M9)*2.5,"")
L10: =IF(COUNT(B10:K10)=10,(B10-1)+(D10-1)+(F10-1)+(H10-1)+(J10-1),"") | M10: =IF(COUNT(B10:K10)=10,(5-C10)+(5-E10)+(5-G10)+(5-I10)+(5-K10),"") | N10: =IF(COUNT(B10:K10)=10,(L10+M10)*2.5,"")
L11: =IF(COUNT(B11:K11)=10,(B11-1)+(D11-1)+(F11-1)+(H11-1)+(J11-1),"") | M11: =IF(COUNT(B11:K11)=10,(5-C11)+(5-E11)+(5-G11)+(5-I11)+(5-K11),"") | N11: =IF(COUNT(B11:K11)=10,(L11+M11)*2.5,"")
L12: =IF(COUNT(B12:K12)=10,(B12-1)+(D12-1)+(F12-1)+(H12-1)+(J12-1),"") | M12: =IF(COUNT(B12:K12)=10,(5-C12)+(5-E12)+(5-G12)+(5-I12)+(5-K12),"") | N12: =IF(COUNT(B12:K12)=10,(L12+M12)*2.5,"")
L13: =IF(COUNT(B13:K13)=10,(B13-1)+(D13-1)+(F13-1)+(H13-1)+(J13-1),"") | M13: =IF(COUNT(B13:K13)=10,(5-C13)+(5-E13)+(5-G13)+(5-I13)+(5-K13),"") | N13: =IF(COUNT(B13:K13)=10,(L13+M13)*2.5,"")
L14: =IF(COUNT(B14:K14)=10,(B14-1)+(D14-1)+(F14-1)+(H14-1)+(J14-1),"") | M14: =IF(COUNT(B14:K14)=10,(5-C14)+(5-E14)+(5-G14)+(5-I14)+(5-K14),"") | N14: =IF(COUNT(B14:K14)=10,(L14+M14)*2.5,"")
L15: =IF(COUNT(B15:K15)=10,(B15-1)+(D15-1)+(F15-1)+(H15-1)+(J15-1),"") | M15: =IF(COUNT(B15:K15)=10,(5-C15)+(5-E15)+(5-G15)+(5-I15)+(5-K15),"") | N15: =IF(COUNT(B15:K15)=10,(L15+M15)*2.5,"")
L16: =IF(COUNT(B16:K16)=10,(B16-1)+(D16-1)+(F16-1)+(H16-1)+(J16-1),"") | M16: =IF(COUNT(B16:K16)=10,(5-C16)+(5-E16)+(5-G16)+(5-I16)+(5-K16),"") | N16: =IF(COUNT(B16:K16)=10,(L16+M16)*2.5,"")
... L39: =IF(COUNT(B39:K39)=10,(B39-1)+(D39-1)+(F39-1)+(H39-1)+(J39-1),"") | M39: =IF(COUNT(B39:K39)=10,(5-C39)+(5-E39)+(5-G39)+(5-I39)+(5-K39),"") | N39: =IF(COUNT(B39:K39)=10,(L39+M39)*2.5,"")
A42: n | B42: =COUNT(N4:N39) -> 1
A43: 平均 | B43: =IF(COUNT(N4:N39)>0,AVERAGE(N4:N39),"") -> 72.5
A44: 標準差 | B44: =IF(COUNT(N4:N39)>1,STDEV(N4:N39),"")
A45: 95% CI 半寬 | B45: =IF(COUNT(N4:N39)>1,TINV(0.05,COUNT(N4:N39)-1)*STDEV(N4:N39)/SQRT(COUNT(N4:N39)),"")
A46: CI 下界 | B46: =IF(COUNT(N4:N39)>1,B43-B45,"")
A47: CI 上界 | B47: =IF(COUNT(N4:N39)>1,B43+B45,"")
A48: 基準 68；≥80 屬優良。CI 用 t 分布（TINV 為雙尾）。

Sheet A_量表
A1: A_量表：信任與驗證意願（1–7）與每工具三題（1–7）
A3: 受試者ID | B3: V1 反映原話 | C3: V2 會回看語證 | D3: V3 理由有幫助 | E3: V4 知道在本機 | F3: V5 當起點 | G3: V6 擔心漏掉 | H3: STT 容易上手 | I3: STT 知道在做什麼 | J3: STT 信任輸出 | K3: OC 容易上手 | L3: OC 知道在做什麼 | M3: OC 信任輸出 | N3: Reader 容易上手 | O3: Reader 知道在做什麼 | P3: Reader 信任輸出
A4: 範例 | B4: 5 | C4: 6 | D4: 5 | E4: 6 | F4: 4 | G4: 5 | H4: 4 | I4: 5 | J4: 5 | K4: 3 | L4: 4 | M4: 4 | N4: 6 | O4: 6 | P4: 5
A41: 平均 | B41: =IF(COUNT(B4:B39)>0,AVERAGE(B4:B39),"") -> 5 | C41: =IF(COUNT(C4:C39)>0,AVERAGE(C4:C39),"") -> 6 | D41: =IF(COUNT(D4:D39)>0,AVERAGE(D4:D39),"") -> 5 | E41: =IF(COUNT(E4:E39)>0,AVERAGE(E4:E39),"") -> 6 | F41: =IF(COUNT(F4:F39)>0,AVERAGE(F4:F39),"") -> 4 | G41: =IF(COUNT(G4:G39)>0,AVERAGE(G4:G39),"") -> 5 | H41: =IF(COUNT(H4:H39)>0,AVERAGE(H4:H39),"") -> 4 | I41: =IF(COUNT(I4:I39)>0,AVERAGE(I4:I39),"") -> 5 | ... P41: =IF(COUNT(P4:P39)>0,AVERAGE(P4:P39),"") -> 5

Sheet PartC_稽核
A1: PartC_稽核：T6 每筆 code 的判定
A2: 每位受試者 12 列。植入 = Y 的列是問題 code（類型 a 語證不支持／b 主句為訪員／c 過度推論）。
A3: 受試者ID | B3: 版面(A/B) | C3: 筆序 | D3: 植入(Y/N) | E3: 植入類型(a/b/c) | F3: 受試者判定 | G3: 信心(1–7) | H3: 時間(秒) | I3: 切換完整上下文(Y/N) | J3: 拒絕理由摘要 | K3: 正確偵測 | L3: 誤拒 | M3: 漏檢
A4: 範例 | B4: A | C4: 3 | D4: Y | E4: a | F4: 不採用 | G4: 6 | H4: 48 | I4: Y | J4: 語證裡沒有說客戶會拒付款 | K4: =IF(AND(D4="Y",F4="不採用"),1,IF(D4="","",0)) -> 1 | L4: =IF(AND(D4="N",F4="不採用"),1,IF(D4="","",0)) -> 0 | M4: =IF(AND(D4="Y",F4="採用"),1,IF(D4="","",0)) -> 0
K5: =IF(AND(D5="Y",F5="不採用"),1,IF(D5="","",0)) | L5: =IF(AND(D5="N",F5="不採用"),1,IF(D5="","",0)) | M5: =IF(AND(D5="Y",F5="採用"),1,IF(D5="","",0))
K6: =IF(AND(D6="Y",F6="不採用"),1,IF(D6="","",0)) | L6: =IF(AND(D6="N",F6="不採用"),1,IF(D6="","",0)) | M6: =IF(AND(D6="Y",F6="採用"),1,IF(D6="","",0))
K7: =IF(AND(D7="Y",F7="不採用"),1,IF(D7="","",0)) | L7: =IF(AND(D7="N",F7="不採用"),1,IF(D7="","",0)) | M7: =IF(AND(D7="Y",F7="採用"),1,IF(D7="","",0))
K8: =IF(AND(D8="Y",F8="不採用"),1,IF(D8="","",0)) | L8: =IF(AND(D8="N",F8="不採用"),1,IF(D8="","",0)) | M8: =IF(AND(D8="Y",F8="採用"),1,IF(D8="","",0))
K9: =IF(AND(D9="Y",F9="不採用"),1,IF(D9="","",0)) | L9: =IF(AND(D9="N",F9="不採用"),1,IF(D9="","",0)) | M9: =IF(AND(D9="Y",F9="採用"),1,IF(D9="","",0))
K10: =IF(AND(D10="Y",F10="不採用"),1,IF(D10="","",0)) | L10: =IF(AND(D10="N",F10="不採用"),1,IF(D10="","",0)) | M10: =IF(AND(D10="Y",F10="採用"),1,IF(D10="","",0))
K11: =IF(AND(D11="Y",F11="不採用"),1,IF(D11="","",0)) | L11: =IF(AND(D11="N",F11="不採用"),1,IF(D11="","",0)) | M11: =IF(AND(D11="Y",F11="採用"),1,IF(D11="","",0))
K12: =IF(AND(D12="Y",F12="不採用"),1,IF(D12="","",0)) | L12: =IF(AND(D12="N",F12="不採用"),1,IF(D12="","",0)) | M12: =IF(AND(D12="Y",F12="採用"),1,IF(D12="","",0))
K13: =IF(AND(D13="Y",F13="不採用"),1,IF(D13="","",0)) | L13: =IF(AND(D13="N",F13="不採用"),1,IF(D13="","",0)) | M13: =IF(AND(D13="Y",F13="採用"),1,IF(D13="","",0))
K14: =IF(AND(D14="Y",F14="不採用"),1,IF(D14="","",0)) | L14: =IF(AND(D14="N",F14="不採用"),1,IF(D14="","",0)) | M14: =IF(AND(D14="Y",F14="採用"),1,IF(D14="","",0))
K15: =IF(AND(D15="Y",F15="不採用"),1,IF(D15="","",0)) | L15: =IF(AND(D15="N",F15="不採用"),1,IF(D15="","",0)) | M15: =IF(AND(D15="Y",F15="採用"),1,IF(D15="","",0))
K16: =IF(AND(D16="Y",F16="不採用"),1,IF(D16="","",0)) | L16: =IF(AND(D16="N",F16="不採用"),1,IF(D16="","",0)) | M16: =IF(AND(D16="Y",F16="採用"),1,IF(D16="","",0))
... K399: =IF(AND(D399="Y",F399="不採用"),1,IF(D399="","",0)) | L399: =IF(AND(D399="N",F399="不採用"),1,IF(D399="","",0)) | M399: =IF(AND(D399="Y",F399="採用"),1,IF(D399="","",0))

Sheet B_執行記錄
A1: B_執行記錄：Part B 每次執行
A2: 凍結參數：5000 字／15 句／半徑 12／保底 5／最低 10／精選開／num_ctx 8192。seal_eval_collect.py 的 summary.csv 可直接貼到 A–N 欄。
A3: 條件代號 | B3: 模型 | C3: 執行方式 | D3: 逐字稿 | E3: run | F3: 開始時間 | G3: 結束時間 | H3: 執行時間(分) | I3: 逾時次數 | J3: 略過片段 | K3: 可定位初始候選 | L3: 通過門檻 | M3: 最後保留 | N3: code 列數 | O3: Seal commit | P3: Ollama 版本／模型 digest | Q3: 雲端 token 數 | R3: 雲端費用 | S3: 備註
A4: L2 | B4: qwen3:8b | C4: 本機 | D4: P01_個人創作者.txt | E4: 1 | F4: 2026-09-20 21:10 | G4: 2026-09-20 21:31 | H4: 21 | I4: 0 | J4: 0 | K4: 26 | L4: 19 | M4: 14 | N4: 14 | O4: cb7e983+ | P4: 0.11.x / sha256:… | S4: 使用前刪除此列

Sheet B_埋點對照表
A1: B_埋點對照表：每份逐字稿的標準答案
A2: 關鍵句必須能在逐字稿中逐字找到且只出現一次；新逐字稿請依同格式續填。行號以逐字稿的行為準（第 1 行 = 第一句訪員）。
A3: 埋點ID | B3: 逐字稿 | C3: 類型 | D3: 行號 | E3: 關鍵句（逐字） | F3: 預期 code 要點 | G3: 給分說明 | H3: 備註
A4: P01-01 | B4: P01_個人創作者.txt | C4: E1 | D4: 4 | E4: 但如果那支片是要接業配、要投廣告的，我就會去買授權的曲子 | F4: 自己發的日常片一律用平台內建免費音樂；只有要接業配或投廣告的影片才購買授權曲 | G4: 1 = 寫出「日常 vs 業配／廣告」的條件與兩種做法；0.5 = 只寫其中一種做法
A5: P01-02 | B5: P01_個人創作者.txt | C5: E2 | D5: 6 | E5: 結果那支片剛好是我那個月流量最好的一支，衝到快十萬，然後就被靜音了 | F5: 用網路找的歌被平台靜音（流量最好的一支）→ 從此不敢再用未授權音樂 → 自己發的一律改用內建 | G5: 1 = 事件＋行為改變；0.5 = 只有事件
A6: P01-03 | B6: P01_個人創作者.txt | C6: E2 | D6: 12 | E6: 我知道這樣很沒有個性，但我寧可沒個性也不要再被靜音一次 | F6: 改用內建音樂的代價是與別人雷同、沒個性，受訪者評價為可接受（「至少片還活著」） | G6: 1 = 代價＋受訪者的評價；0.5 = 只有代價
A7: P01-04 | B7: P01_個人創作者.txt | C7: E9 | D7: 22 | E7: 有對的那個完播率高滿多的，大概差了快兩成 | F7: 自行做兩版本 A/B 測試，對節拍版本完播率高近兩成，因此願意每支花兩小時對節拍（與 P02、P03 相反） | G7: 1 = 測試＋結果＋願意投入時間；0.5 = 只寫花兩小時
A8: P01-05 | B8: P01_個人創作者.txt | C8: E5 | D8: 24 | E8: 他們說這個系統會提供版權提醒，就是說你放的音樂有問題它會先跟你講。可是我沒收到 | F8: 平台宣稱的版權提醒沒有出現（影片直接被靜音、從留言才知道）→ 不再信任該功能，改為自己先查歌能不能用 | G8: 1 = 落差＋後續行為；0.5 = 只有抱怨。注意此句以第一人稱轉述，舊版會誤判為訪員
A9: P01-06 | B9: P01_個人創作者.txt | C9: E6 | D9: 28 | E9: 有時候找不到資料我就直接放棄那首 | F9: 自己土法查歌名有無被檢舉（5 分鐘到半小時），查不到就放棄該曲；最麻煩的是查完後仍不確定的懸置感 | G9: 1 = 做法＋代價（時間或不確定感）；0.5 = 只有做法
A10: P01-07 | B10: P01_個人創作者.txt | C10: E3 | D10: 38 | E10: 音效只用來補畫面沒講清楚的東西，不是用來加戲的 | F10: 曾因加太多音效被留言說聽起來很累而收斂，現在的原則是音效只補畫面沒講清楚的部分 | G10: 1 = 教訓＋原則；0.5 = 只有原則
A11: P01-08 | B11: P01_個人創作者.txt | C11: E8 | D11: 32 | E11: 大概三年了 | F11: 不應產生 code（只有背景、沒有理由） | G11: 若產生以此為主句的 code，記為排除違反
A12: P01-09 | B12: P01_個人創作者.txt | C12: E7 | D12: 13 | E12: 所以是一種取捨。 | F12: 訪員的重述，不應作為主句 | G12: 若成為主句，記為排除違反
A13: P02-01 | B13: P02_接案剪輯師.txt | C13: E2 | D13: 12 | E13: 我就去音效庫抓了一些聲音進去。像是門鈴、手機震動、還有那種遠遠的車聲 | F13: 客戶無聲拍攝的素材看起來像廣告目錄 → 鋪上低音量環境音（門鈴、手機震動、車聲）→ 留言變成「像在他家」、完播率高約三成 → 現在幾乎每支都加 | G13: 1 = 觸發＋做法＋結果；0.5 = 缺其一
A14: P02-02 | B14: P02_接案剪輯師.txt | C14: E3 | D14: 18 | E14: 我後來也不太解釋，因為解釋了他可能會叫我拿掉 | F14: 客戶只感覺「比較好」卻說不出原因；受訪者選擇不解釋音效，以免客戶要求拿掉 | G14: 1 = 行為＋理由；0.5 = 只有行為
A15: P02-03 | B15: P02_接案剪輯師.txt | C15: E1 | D15: 24 | E15: 免費的我會用，但只用那種標明可商用而且我下載得到授權證明的 | F15: 接案者一定用有授權的音樂（出事由自己負責、合約載明）；免費音樂只在標明可商用且能取得授權證明時使用 | G15: 1 = 條件＋理由；0.5 = 只寫一定用授權
... A29: P03-09 | B29: P03_學生創作者.txt | C29: E8 | D29: 2 | E29: 我是學生，就是課餘拍 | F29: 不應產生 code（背景敘述） | G29: 若產生以此為主句的 code，記為排除違反
A31: 行號為概略值（以「訪員：」開頭的第一行為第 1 行），請在凍結逐字稿後核對。新增逐字稿的埋點由 Prompt A 的埋點清單貼入。

Sheet B_埋點評分
A1: B_埋點評分：長格式
A2: 每列 = 一個埋點 × 一個條件 × 一次 run。得分 1／0.5／0（給分說明見對照表）。seal_eval_collect.py 的 planted_autocheck.csv 可貼入後由人工修正。
A3: 埋點ID | B3: 逐字稿 | C3: 類型 | D3: 條件代號 | E3: run | F3: 自動比對(命中/未命中) | G3: 人工得分(1/0.5/0) | H3: 對應 code（貼上） | I3: 評分者 | J3: 備註
A4: P01-01 | B4: P01_個人創作者.txt | C4: E1 | D4: L2 | E4: 1 | F4: 命中 | G4: 1 | H4: 自己發的日常片用平台內建音樂，但接業配或投廣告的影片會購買授權曲，因為曾被靜音 | I4: PY | J4: 使用前刪除此列

Sheet B_人工評分
A1: B_人工評分：每筆 code 的盲評
A2: 貼入 seal_eval_collect.py 的 codes_long.csv（A–J 欄），盲評時隱藏 A 欄（條件）。
A3: 條件代號 | B3: run | C3: 逐字稿 | D3: 序號 | E3: segment_id | F3: speaker | G3: evidence_quote | H3: code | I3: why_this_code | J3: analytic_score | K3: 評分者 | L3: 參照對應(1/0) | M3: 對應的參照 code ID | N3: 語證支持(2/1/0) | O3: 過度推論(1/0) | P3: 排除違反(1/0) | Q3: 備註
A4: L2 | B4: 1 | C4: P01_個人創作者.txt | D4: 1 | E4: S0004 | F4: 受訪者 | G4: 但如果那支片是要接業配、要投廣告的，我就會去買授權的曲子 | H4: 自己發的日常片用內建音樂，接業配或投廣告才買授權曲 | I4: 受訪者明確區分兩種情境的做法… | J4: 74 | K4: PY | L4: 1 | M4: R-P01-02 | N4: 2 | O4: 0 | P4: 0 | Q4: 使用前刪除此列

Sheet B_研究方向評分
A1: B_研究方向評分：尾頁「海豹覺得的研究方向」
A3: 條件代號 | B3: run | C3: 逐字稿 | D3: 方向序號 | E3: 方向名稱 | F3: 有效(1/0) | G3: 可信度(1–5) | H3: 語證扣合(1–5) | I3: 引用 code 數 | J3: 評分者 | K3: 備註
A4: L2 | B4: 1 | C4: P01_個人創作者.txt | D4: 1 | E4: 平台處罰事件如何改寫創作者的風險策略 | F4: 1 | G4: 4 | H4: 4 | I4: 3 | J4: PY | K4: 使用前刪除此列

Sheet B_盲評代碼
A1: B_盲評代碼：條件 ↔ 盲評代碼
A2: 盲評期間請隱藏此分頁與 B_人工評分 的條件欄。
A3: 條件代號 | B3: 模型 | C3: 盲評代碼 | D3: 資料生成器（不得等於 C1/C2）
A4: L1 | B4: qwen3:4b | C4: M-δ | D4: （填入生成合成資料的聊天機器人與版本）
A5: L2 | B5: qwen3:8b | C5: M-α
A6: L3 | B6: qwen3:14b | C6: M-ζ
A7: L4 | B7: qwen3:32b | C7: M-β
A8: C1 | B8: （雲端 A） | C8: M-γ
A9: C2 | B9: （雲端 B） | C9: M-ε

Sheet STT_去識別化檢核
A1: STT_去識別化檢核：PII 對照表與結果
A2: 每個埋點 × 每個條件一列。結果：遮蔽（正確替換）／洩漏（原文仍在）／過度（不該遮卻遮）。陷阱項預期輸出為「保留」。
A3: 音檔 | B3: 條件 | C3: 類型 | D3: 原文 | E3: 預期輸出 | F3: 出現行 | G3: 結果 | H3: 代稱是否一致(Y/N/–) | I3: 備註
A4: 測試音檔_01 | B4: large-v3+qwen3:8b | C4: 人名 | D4: 林佳蓉（阿蓉） | E4: [人物1] | F4: 3, 9, 15 | G4: 遮蔽 | H4: Y | I4: 使用前刪除此列
A5: 測試音檔_01 | B5: large-v3+qwen3:8b | C5: 手機(口語) | D5: 零九一二三四五六七八 | E5: [手機號碼] | F5: 7 | G5: 洩漏 | H5: – | I5: 口語中文數字未被 regex 捕捉
A6: 測試音檔_01 | B6: large-v3+qwen3:8b | C6: 陷阱-年份 | D6: 2024 年 | E6: 保留 | F6: 11 | G6: 遮蔽 | H6: – | I6: 過度遮蔽

Sheet STT_轉錄品質
A1: STT_轉錄品質
A2: CER 以金標逐字稿（錄音後人工修正的腳本）為參照，去標點、全半形正規化後計算（jiwer.cer）。
A3: 音檔 | B3: 條件 | C3: 環境 | D3: 朗讀組 | E3: CER | F3: 講者歸屬正確率 | G3: 幻覺攔截／重試次數 | H3: 潤稿改動句比例 | I3: 抽樣意義改變句數/抽樣數 | J3: 處理時間(分) | K3: 備註
A4: 測試音檔_01 | B4: large-v3 | C4: quiet | D4: g1 | E4: 0.062 | F4: 0.94 | G4: 0 | H4: 0.31 | I4: 1/20 | J4: 4.5 | K4: 使用前刪除此列

Sheet 彙總
A1: 彙總（自動）
A2: 所有公式參考各分頁；範例列會被算進去，正式使用前請刪除範例列。
A4: Part A 易用性
A5: 指標 | B5: 值 | C5: 說明
A6: SUS 平均 | B6: =A_SUS!B43 -> 72.5 | C6: 基準 68
A7: SUS 95% CI 下界／上界 | B7: =IF(A_SUS!B46="","",TEXT(A_SUS!B46,"0.0")&" – "&TEXT(A_SUS!B47,"0.0")) | C7: t 分布
A8: 受試者數 | B8: =A_SUS!B42 -> 1
A9: T0 平均成功分數 | B9: =IFERROR(AVERAGEIF(A_任務記錄!B:B,"T0",A_任務記錄!I:I),"") | C9: 1 = 獨立完成；0.5 = 需提示；0 = 未完成
A10: T1 平均成功分數 | B10: =IFERROR(AVERAGEIF(A_任務記錄!B:B,"T1",A_任務記錄!I:I),"") | C10: 1 = 獨立完成；0.5 = 需提示；0 = 未完成
A11: T2 平均成功分數 | B11: =IFERROR(AVERAGEIF(A_任務記錄!B:B,"T2",A_任務記錄!I:I),"") | C11: 1 = 獨立完成；0.5 = 需提示；0 = 未完成
A12: T3 平均成功分數 | B12: =IFERROR(AVERAGEIF(A_任務記錄!B:B,"T3",A_任務記錄!I:I),"") | C12: 1 = 獨立完成；0.5 = 需提示；0 = 未完成
A13: T4 平均成功分數 | B13: =IFERROR(AVERAGEIF(A_任務記錄!B:B,"T4",A_任務記錄!I:I),"") -> 0.5 | C13: 1 = 獨立完成；0.5 = 需提示；0 = 未完成
A14: T5 平均成功分數 | B14: =IFERROR(AVERAGEIF(A_任務記錄!B:B,"T5",A_任務記錄!I:I),"") | C14: 1 = 獨立完成；0.5 = 需提示；0 = 未完成
A15: T7 平均成功分數 | B15: =IFERROR(AVERAGEIF(A_任務記錄!B:B,"T7",A_任務記錄!I:I),"") | C15: 1 = 獨立完成；0.5 = 需提示；0 = 未完成
A16: T1 主動時間平均(分) | B16: =IFERROR(AVERAGEIF(A_任務記錄!B:B,"T1",A_任務記錄!F:F),"") | C16: 中位數與四分位請在分析時另算
A17: T3 主動時間平均(分) | B17: =IFERROR(AVERAGEIF(A_任務記錄!B:B,"T3",A_任務記錄!F:F),"") | C17: 中位數與四分位請在分析時另算
A18: T4 主動時間平均(分) | B18: =IFERROR(AVERAGEIF(A_任務記錄!B:B,"T4",A_任務記錄!F:F),"") -> 9 | C18: 中位數與四分位請在分析時另算
A19: T5 主動時間平均(分) | B19: =IFERROR(AVERAGEIF(A_任務記錄!B:B,"T5",A_任務記錄!F:F),"") | C19: 中位數與四分位請在分析時另算
A20: 嚴重度 ≥3 事件數 | B20: =COUNTIF(A_觀察事件!G:G,">=3") -> 0
A21: V2「會回看語證」平均 | B21: =A_量表!C41 -> 6
A22: V4「知道在本機」平均 | B22: =A_量表!E41 -> 6
A24: Part C 驗證行為
A25: 指標 | B25: 版面 A（顯示理由） | C25: 版面 B（隱藏理由）
A26: 問題 code 偵測率 | B26: =IFERROR(SUMIFS(PartC_稽核!K:K,PartC_稽核!B:B,"A",PartC_稽核!D:D,"Y")/COUNTIFS(PartC_稽核!B:B,"A",PartC_稽核!D:D,"Y"),"") -> 1 | C26: =IFERROR(SUMIFS(PartC_稽核!K:K,PartC_稽核!B:B,"B",PartC_稽核!D:D,"Y")/COUNTIFS(PartC_稽核!B:B,"B",PartC_稽核!D:D,"Y"),"")
A27: 誤拒率（正常 code 被拒絕） | B27: =IFERROR(SUMIFS(PartC_稽核!L:L,PartC_稽核!B:B,"A",PartC_稽核!D:D,"N")/COUNTIFS(PartC_稽核!B:B,"A",PartC_稽核!D:D,"N"),"") | C27: =IFERROR(SUMIFS(PartC_稽核!L:L,PartC_稽核!B:B,"B",PartC_稽核!D:D,"N")/COUNTIFS(PartC_稽核!B:B,"B",PartC_稽核!D:D,"N"),"")
A28: 平均信心(1–7) | B28: =IFERROR(AVERAGEIFS(PartC_稽核!G:G,PartC_稽核!B:B,"A"),"") -> 6 | C28: =IFERROR(AVERAGEIFS(PartC_稽核!G:G,PartC_稽核!B:B,"B"),"")
A29: 平均每筆時間(秒) | B29: =IFERROR(AVERAGEIFS(PartC_稽核!H:H,PartC_稽核!B:B,"A"),"") -> 48 | C29: =IFERROR(AVERAGEIFS(PartC_稽核!H:H,PartC_稽核!B:B,"B"),"")
A30: 切換完整上下文比例 | B30: =IFERROR(COUNTIFS(PartC_稽核!B:B,"A",PartC_稽核!I:I,"Y")/COUNTIFS(PartC_稽核!B:B,"A",PartC_稽核!F:F,"<>"),"") -> 1 | C30: =IFERROR(COUNTIFS(PartC_稽核!B:B,"B",PartC_稽核!I:I,"Y")/COUNTIFS(PartC_稽核!B:B,"B",PartC_稽核!F:F,"<>"),"")
A32: Part B 效能比較（各條件）
A33: 指標 | B33: L1 | C33: L2 | D33: L3 | E33: L4 | F33: C1 | G33: C2 | H33: 說明
A34: 埋點召回率 | B34: =IFERROR(AVERAGEIFS(B_埋點評分!G:G,B_埋點評分!D:D,"L1"),"") | C34: =IFERROR(AVERAGEIFS(B_埋點評分!G:G,B_埋點評分!D:D,"L2"),"") -> 1 | D34: =IFERROR(AVERAGEIFS(B_埋點評分!G:G,B_埋點評分!D:D,"L3"),"") | E34: =IFERROR(AVERAGEIFS(B_埋點評分!G:G,B_埋點評分!D:D,"L4"),"") | F34: =IFERROR(AVERAGEIFS(B_埋點評分!G:G,B_埋點評分!D:D,"C1"),"") | G34: =IFERROR(AVERAGEIFS(B_埋點評分!G:G,B_埋點評分!D:D,"C2"),"") | H34: 人工得分平均（含 0）
A35: 參照對應率（精確） | B35: =IFERROR(AVERAGEIFS(B_人工評分!L:L,B_人工評分!A:A,"L1"),"") | C35: =IFERROR(AVERAGEIFS(B_人工評分!L:L,B_人工評分!A:A,"L2"),"") -> 1 | D35: =IFERROR(AVERAGEIFS(B_人工評分!L:L,B_人工評分!A:A,"L3"),"") | E35: =IFERROR(AVERAGEIFS(B_人工評分!L:L,B_人工評分!A:A,"L4"),"") | F35: =IFERROR(AVERAGEIFS(B_人工評分!L:L,B_人工評分!A:A,"C1"),"") | G35: =IFERROR(AVERAGEIFS(B_人工評分!L:L,B_人工評分!A:A,"C2"),"") | H35: 與參照 codebook 對上的 code 比例
A36: 語證支持平均(0–2) | B36: =IFERROR(AVERAGEIFS(B_人工評分!N:N,B_人工評分!A:A,"L1"),"") | C36: =IFERROR(AVERAGEIFS(B_人工評分!N:N,B_人工評分!A:A,"L2"),"") -> 2 | D36: =IFERROR(AVERAGEIFS(B_人工評分!N:N,B_人工評分!A:A,"L3"),"") | E36: =IFERROR(AVERAGEIFS(B_人工評分!N:N,B_人工評分!A:A,"L4"),"") | F36: =IFERROR(AVERAGEIFS(B_人工評分!N:N,B_人工評分!A:A,"C1"),"") | G36: =IFERROR(AVERAGEIFS(B_人工評分!N:N,B_人工評分!A:A,"C2"),"")
A37: 語證完整支持比例 | B37: =IFERROR(COUNTIFS(B_人工評分!A:A,"L1",B_人工評分!N:N,2)/COUNTIFS(B_人工評分!A:A,"L1",B_人工評分!N:N,"<>"),"") | C37: =IFERROR(COUNTIFS(B_人工評分!A:A,"L2",B_人工評分!N:N,2)/COUNTIFS(B_人工評分!A:A,"L2",B_人工評分!N:N,"<>"),"") -> 1 | D37: =IFERROR(COUNTIFS(B_人工評分!A:A,"L3",B_人工評分!N:N,2)/COUNTIFS(B_人工評分!A:A,"L3",B_人工評分!N:N,"<>"),"") | E37: =IFERROR(COUNTIFS(B_人工評分!A:A,"L4",B_人工評分!N:N,2)/COUNTIFS(B_人工評分!A:A,"L4",B_人工評分!N:N,"<>"),"") | F37: =IFERROR(COUNTIFS(B_人工評分!A:A,"C1",B_人工評分!N:N,2)/COUNTIFS(B_人工評分!A:A,"C1",B_人工評分!N:N,"<>"),"") | G37: =IFERROR(COUNTIFS(B_人工評分!A:A,"C2",B_人工評分!N:N,2)/COUNTIFS(B_人工評分!A:A,"C2",B_人工評分!N:N,"<>"),"") | H37: 評 2 的比例
A38: 過度推論率 | B38: =IFERROR(AVERAGEIFS(B_人工評分!O:O,B_人工評分!A:A,"L1"),"") | C38: =IFERROR(AVERAGEIFS(B_人工評分!O:O,B_人工評分!A:A,"L2"),"") -> 0 | D38: =IFERROR(AVERAGEIFS(B_人工評分!O:O,B_人工評分!A:A,"L3"),"") | E38: =IFERROR(AVERAGEIFS(B_人工評分!O:O,B_人工評分!A:A,"L4"),"") | F38: =IFERROR(AVERAGEIFS(B_人工評分!O:O,B_人工評分!A:A,"C1"),"") | G38: =IFERROR(AVERAGEIFS(B_人工評分!O:O,B_人工評分!A:A,"C2"),"")
A39: 排除違反率 | B39: =IFERROR(AVERAGEIFS(B_人工評分!P:P,B_人工評分!A:A,"L1"),"") | C39: =IFERROR(AVERAGEIFS(B_人工評分!P:P,B_人工評分!A:A,"L2"),"") -> 0 | D39: =IFERROR(AVERAGEIFS(B_人工評分!P:P,B_人工評分!A:A,"L3"),"") | E39: =IFERROR(AVERAGEIFS(B_人工評分!P:P,B_人工評分!A:A,"L4"),"") | F39: =IFERROR(AVERAGEIFS(B_人工評分!P:P,B_人工評分!A:A,"C1"),"") | G39: =IFERROR(AVERAGEIFS(B_人工評分!P:P,B_人工評分!A:A,"C2"),"") | H39: 主句為訪員／背景／短回應
A40: 研究方向可信度(1–5) | B40: =IFERROR(AVERAGEIFS(B_研究方向評分!G:G,B_研究方向評分!A:A,"L1"),"") | C40: =IFERROR(AVERAGEIFS(B_研究方向評分!G:G,B_研究方向評分!A:A,"L2"),"") -> 4 | D40: =IFERROR(AVERAGEIFS(B_研究方向評分!G:G,B_研究方向評分!A:A,"L3"),"") | E40: =IFERROR(AVERAGEIFS(B_研究方向評分!G:G,B_研究方向評分!A:A,"L4"),"") | F40: =IFERROR(AVERAGEIFS(B_研究方向評分!G:G,B_研究方向評分!A:A,"C1"),"") | G40: =IFERROR(AVERAGEIFS(B_研究方向評分!G:G,B_研究方向評分!A:A,"C2"),"")
A41: 研究方向語證扣合(1–5) | B41: =IFERROR(AVERAGEIFS(B_研究方向評分!H:H,B_研究方向評分!A:A,"L1"),"") | C41: =IFERROR(AVERAGEIFS(B_研究方向評分!H:H,B_研究方向評分!A:A,"L2"),"") -> 4 | D41: =IFERROR(AVERAGEIFS(B_研究方向評分!H:H,B_研究方向評分!A:A,"L3"),"") | E41: =IFERROR(AVERAGEIFS(B_研究方向評分!H:H,B_研究方向評分!A:A,"L4"),"") | F41: =IFERROR(AVERAGEIFS(B_研究方向評分!H:H,B_研究方向評分!A:A,"C1"),"") | G41: =IFERROR(AVERAGEIFS(B_研究方向評分!H:H,B_研究方向評分!A:A,"C2"),"")
A42: 平均執行時間(分) | B42: =IFERROR(AVERAGEIFS(B_執行記錄!H:H,B_執行記錄!A:A,"L1"),"") | C42: =IFERROR(AVERAGEIFS(B_執行記錄!H:H,B_執行記錄!A:A,"L2"),"") -> 21 | D42: =IFERROR(AVERAGEIFS(B_執行記錄!H:H,B_執行記錄!A:A,"L3"),"") | E42: =IFERROR(AVERAGEIFS(B_執行記錄!H:H,B_執行記錄!A:A,"L4"),"") | F42: =IFERROR(AVERAGEIFS(B_執行記錄!H:H,B_執行記錄!A:A,"C1"),"") | G42: =IFERROR(AVERAGEIFS(B_執行記錄!H:H,B_執行記錄!A:A,"C2"),"")
A43: 平均逾時次數 | B43: =IFERROR(AVERAGEIFS(B_執行記錄!I:I,B_執行記錄!A:A,"L1"),"") | C43: =IFERROR(AVERAGEIFS(B_執行記錄!I:I,B_執行記錄!A:A,"L2"),"") -> 0 | D43: =IFERROR(AVERAGEIFS(B_執行記錄!I:I,B_執行記錄!A:A,"L3"),"") | E43: =IFERROR(AVERAGEIFS(B_執行記錄!I:I,B_執行記錄!A:A,"L4"),"") | F43: =IFERROR(AVERAGEIFS(B_執行記錄!I:I,B_執行記錄!A:A,"C1"),"") | G43: =IFERROR(AVERAGEIFS(B_執行記錄!I:I,B_執行記錄!A:A,"C2"),"")
...
